#### 1.
```
class Main {
   public static void main(String args[]) {
      try {
         throw 10;
      }
      catch(int e) {
         System.out.println("Got the  Exception " + e);
      }
  }
}
```
编译错误。  

#### 2.
```
class Test extends Exception { }
  
class Main {
   public static void main(String args[]) { 
      try {
         throw new Test();
      }
      catch(Test t) {
         System.out.println("Got the Test Exception");
      }
      finally {
         System.out.println("Inside finally block ");
      }
  }
}
```
运行结果：
```
Got the Test Exception
Inside finally block
```
#### 3.
```
class Main {
   public static void main(String args[]) {
      int x = 0;
      int y = 10;
      int z = y/x;
  }
}
```
运行错误，除数不能为0。可以做以下修改：
```
class Main {
    public static void main(String args[]) {
        int x = 0;
        int y = 10;

        try {
            if(x == 0) throw new Exception();
            System.out.println( y/x );
        } catch (Exception e) {
//            e.printStackTrace();
            System.out.println("被除数x不能为0");
        }
    }
}
```
#### 4.
```
class Base extends Exception {}
class Derived extends Base  {}
 
public class Main {
  public static void main(String args[]) {
   // some other stuff
   try {
       // Some monitored code
       throw new Derived();
    }
    catch(Base b)     { 
       System.out.println("Caught base class exception"); 
    }
    catch(Derived d)  { 
       System.out.println("Caught derived class exception"); 
    }
  }
} 
```
编译错误，异常已捕捉。
#### 5.
```
class Test
{
    public static void main (String[] args)
    {
        try
        {
            int a = 0;
            System.out.println ("a = " + a);
            int b = 20 / a;
            System.out.println ("b = " + b);
        }
 
        catch(ArithmeticException e)
        {
            System.out.println ("Divide by zero error");
        }
 
        finally
        {
            System.out.println ("inside the finally block");
        }
    }
}
```
运行结果：
```
a = 0
Divide by zero error
inside the finally block
```
#### 6.
```
class Test
{
    public static void main(String[] args)
    {
        try
        {
            int a[]= {1, 2, 3, 4};
            for (int i = 1; i <= 4; i++)
            {
                System.out.println ("a[" + i + "]=" + a[i] + "n");
            }
        }
         
        catch (Exception e)
        {
            System.out.println ("error = " + e);
        }
         
        catch (ArrayIndexOutOfBoundsException e)
        {
            System.out.println ("ArrayIndexOutOfBoundsException");
        }
    }
}
```
#### 7.
```
class Test
{
    String str = "a";
 
    void A()
    {
        try
        {
            str +="b";
            B();
        }
        catch (Exception e)
        {
            str += "c";
        }
    }
 
    void B() throws Exception
    {
        try
        {
            str += "d";
            C();
        }
        catch(Exception e)
        {
            throw new Exception();
        }
        finally
        {
            str += "e";
        }
 
        str += "f";
 
    }
     
    void C() throws Exception
    {
        throw new Exception();
    }
 
    void display()
    {
        System.out.println(str);
    }
 
    public static void main(String[] args)
    {
        Test object = new Test();
        object.A();
        object.display();
    }
 
}
```
运行结果：`abdec`
#### 8.
```
class Test
{   int count = 0;
 
    void A() throws Exception
    {
        try
        {
            count++;
             
            try
            {
                count++;
 
                try
                {
                    count++;
                    throw new Exception();
 
                }
                 
                catch(Exception ex)
                {
                    count++;
                    throw new Exception();
                }
            }
             
            catch(Exception ex)
            {
                count++;
            }
        }
         
        catch(Exception ex)
        {
            count++;
        }
 
    }
 
    void display()
    {
        System.out.println(count);
    }
 
    public static void main(String[] args) throws Exception
    {
        Test obj = new Test();
        obj.A();
        obj.display();
    }
}
```
运行结果：`5`

#### 9.方法返回值是
```
public int myMethod(){

  try {

  return 1;

  }

  Catch (Exception e){

  return 2;

  }

  finally{

  return 3;

 }

}
```
#### 10.

```
 try {

      File file = new File("filename.txt");

      Scanner sc = new Scanner(file);

      throw new IOException();
    }

    catch (FileNotFoundException e) {

      System.out.println("FileNotFoundException called!!!");

    }

    catch (IOException e) {

      System.out.println("IOException called!!!");

    } 

```
运行结果：`FileNotFoundException called!!!`
#### 11.

```
try {

      File file = new File("filename.txt");

      Scanner sc = new Scanner(file);

      throw new IOException();
    }

    catch (IOException e) {

      System.out.println("IOException called!!!");

    } 
```
运行结果：`IOException called!!!`